[2024-01-05T03:11:18.998+0300] {taskinstance.py:1090} INFO - Dependencies all met for dep_context=non-requeueable deps ti=<TaskInstance: youtube_comments_score.get_data scheduled__2023-01-01T11:30:00+00:00 [queued]>
[2024-01-05T03:11:19.010+0300] {taskinstance.py:1090} INFO - Dependencies all met for dep_context=requeueable deps ti=<TaskInstance: youtube_comments_score.get_data scheduled__2023-01-01T11:30:00+00:00 [queued]>
[2024-01-05T03:11:19.010+0300] {taskinstance.py:1288} INFO - 
--------------------------------------------------------------------------------
[2024-01-05T03:11:19.010+0300] {taskinstance.py:1289} INFO - Starting attempt 2 of 2
[2024-01-05T03:11:19.010+0300] {taskinstance.py:1290} INFO - 
--------------------------------------------------------------------------------
[2024-01-05T03:11:19.019+0300] {taskinstance.py:1309} INFO - Executing <Task(BashOperator): get_data> on 2023-01-01 11:30:00+00:00
[2024-01-05T03:11:19.026+0300] {standard_task_runner.py:55} INFO - Started process 169213 to run task
[2024-01-05T03:11:19.036+0300] {standard_task_runner.py:82} INFO - Running: ['airflow', 'tasks', 'run', 'youtube_comments_score', 'get_data', 'scheduled__2023-01-01T11:30:00+00:00', '--job-id', '394', '--raw', '--subdir', 'DAGS_FOLDER/youtube_comments_score.py', '--cfg-path', '/tmp/tmpkgu2p3zv']
[2024-01-05T03:11:19.037+0300] {standard_task_runner.py:83} INFO - Job 394: Subtask get_data
[2024-01-05T03:11:19.130+0300] {task_command.py:389} INFO - Running <TaskInstance: youtube_comments_score.get_data scheduled__2023-01-01T11:30:00+00:00 [running]> on host prod-srv
[2024-01-05T03:11:19.211+0300] {taskinstance.py:1516} INFO - Exporting the following env vars:
AIRFLOW_CTX_DAG_OWNER=admin
AIRFLOW_CTX_DAG_ID=youtube_comments_score
AIRFLOW_CTX_TASK_ID=get_data
AIRFLOW_CTX_EXECUTION_DATE=2023-01-01T11:30:00+00:00
AIRFLOW_CTX_TRY_NUMBER=2
AIRFLOW_CTX_DAG_RUN_ID=scheduled__2023-01-01T11:30:00+00:00
[2024-01-05T03:11:19.211+0300] {subprocess.py:63} INFO - Tmp dir root location: 
 /tmp
[2024-01-05T03:11:19.212+0300] {subprocess.py:75} INFO - Running command: ['/usr/bin/bash', '-c', 'python3 /home/igor/xflow/scripts/get_data.py']
[2024-01-05T03:11:19.217+0300] {subprocess.py:86} INFO - Output:
[2024-01-05T03:11:20.248+0300] {subprocess.py:93} INFO - Traceback (most recent call last):
[2024-01-05T03:11:20.248+0300] {subprocess.py:93} INFO -   File "/home/igor/xflow/scripts/get_data.py", line 19, in <module>
[2024-01-05T03:11:20.248+0300] {subprocess.py:93} INFO -     video = api.search_by_keywords(q=query, search_type=["video"], count=10, limit=30)
[2024-01-05T03:11:20.248+0300] {subprocess.py:93} INFO -   File "/home/igor/xflow/venv/lib/python3.10/site-packages/pyyoutube/api.py", line 1750, in search_by_keywords
[2024-01-05T03:11:20.249+0300] {subprocess.py:93} INFO -     return self.search(
[2024-01-05T03:11:20.249+0300] {subprocess.py:93} INFO -   File "/home/igor/xflow/venv/lib/python3.10/site-packages/pyyoutube/api.py", line 1683, in search
[2024-01-05T03:11:20.249+0300] {subprocess.py:93} INFO -     res_data = self.paged_by_page_token(resource="search", args=args, count=count)
[2024-01-05T03:11:20.249+0300] {subprocess.py:93} INFO -   File "/home/igor/xflow/venv/lib/python3.10/site-packages/pyyoutube/api.py", line 487, in paged_by_page_token
[2024-01-05T03:11:20.250+0300] {subprocess.py:93} INFO -     data = self._parse_response(resp)  # origin response
[2024-01-05T03:11:20.250+0300] {subprocess.py:93} INFO -   File "/home/igor/xflow/venv/lib/python3.10/site-packages/pyyoutube/api.py", line 327, in _parse_response
[2024-01-05T03:11:20.250+0300] {subprocess.py:93} INFO -     raise PyYouTubeException(response)
[2024-01-05T03:11:20.250+0300] {subprocess.py:93} INFO - pyyoutube.error.PyYouTubeException: YouTubeException(status_code=403,message=The request cannot be completed because you have exceeded your <a href="/youtube/v3/getting-started#quota">quota</a>.)
[2024-01-05T03:11:20.370+0300] {subprocess.py:97} INFO - Command exited with return code 1
[2024-01-05T03:11:20.388+0300] {taskinstance.py:1776} ERROR - Task failed with exception
Traceback (most recent call last):
  File "/home/igor/xflow/venv/lib/python3.10/site-packages/airflow/operators/bash.py", line 196, in execute
    raise AirflowException(
airflow.exceptions.AirflowException: Bash command failed. The command returned a non-zero exit code 1.
[2024-01-05T03:11:20.391+0300] {taskinstance.py:1327} INFO - Marking task as FAILED. dag_id=youtube_comments_score, task_id=get_data, execution_date=20230101T113000, start_date=20240105T001118, end_date=20240105T001120
[2024-01-05T03:11:20.401+0300] {standard_task_runner.py:100} ERROR - Failed to execute job 394 for task get_data (Bash command failed. The command returned a non-zero exit code 1.; 169213)
[2024-01-05T03:11:20.407+0300] {local_task_job.py:212} INFO - Task exited with return code 1
[2024-01-05T03:11:20.434+0300] {taskinstance.py:2596} INFO - 0 downstream tasks scheduled from follow-on schedule check
